Workbook

Sheet 実施状況
B1: ※メッセージ
B2: 運営事務局です。
B3: テストが未実施となっております。
B4: お手数ですが、実施をお願いいたします。
F5: {コースデータ}
A6: 受講者ID | B6: 氏名 | C6: 会社名 | D6: クラス名 | E6: ランク | F6: テスト | G6: アンケート
A7: {ユーザーデータ} | F7: {実施データ}

Sheet サマリ
B2: 研修コース名 | C2: テスト結果 | F2: アンケート結果
C3: 全体
C4: 平均点 | D4: 中央値 | E4: 修了率 | F4: 総合 評価 | G4: 目的 達成度 | H4: 学習 理解度 | I4: 業務 適用度 | J4: 講義 評価 | K4: 演習 評価 | L4: 教材 評価 | M4: 講師 評価 | N4: 研修 日数 | O4: 学習 環境
B5: {結果データ}
B6: ビジネス基礎 （Day5）
B9: 差分 | C9: -

Sheet 経年比較（前年同じFMT）
B2: 研修コース名 | D2: 年度 | E2: テスト結果 | H2: アンケート結果
E3: 全体
E4: 平均点 | F4: 中央値 | G4: 修了率 | H4: 総合 評価 | I4: 目的 達成度 | J4: 学習 理解度 | K4: 業務 適用度 | L4: 講義 評価 | M4: 演習 評価 | N4: 教材 評価 | O4: 講師 評価 | P4: 研修 日数 | Q4: 学習 環境
B5: ビジネス | C5: ビジネス基礎 (Day1-５) | D5: FY2025 | H5: =#REF! -> #REF! | I5: =#REF! -> #REF! | J5: =#REF! -> #REF! | K5: =#REF! -> #REF! | L5: =#REF! -> #REF! | M5: =#REF! -> #REF! | N5: =#REF! -> #REF! | O5: =#REF! -> #REF! | ... Q5: =#REF! -> #REF! | S5: ※2023のみビジネス基礎Day1-4
D6: FY2024 | H6: 4.7906137 | I6: 4.4548736 | J6: 4.4368231 | K6: 4.3826715 | L6: 4.6642599 | M6: 4.5595668 | N6: 4.6209386 | O6: 4.7545126 | P6: 4.2599278 | Q6: 4.2418773 | S6: Day5は独立（ロールプレイ部分）
D7: FY2023 | H7: 4.6782609 | I7: 4.2434783 | J7: 4.3347826 | K7: 4.1869565 | L7: 4.4173913 | M7: 4.3956522 | N7: 4.426087 | O7: 4.5652174 | P7: 4.0086957 | Q7: 4.0434783
C8: 差分 | E8: - | G8: - | H8: =H5-H6 -> #REF! | I8: =I5-I6 -> #REF! | J8: =J5-J6 -> #REF! | K8: =K5-K6 -> #REF! | L8: =L5-L6 -> #REF! | M8: =M5-M6 -> #REF! | N8: =N5-N6 -> #REF! | O8: =O5-O6 -> #REF! | ... Q8: =Q5-Q6 -> #REF!
C9: ビジネス基礎 （Day5） | D9: FY2025 | H9: ='ビジネス基礎（Day5)'!A2 -> #DIV/0! | I9: ='ビジネス基礎（Day5)'!B2 -> #DIV/0! | J9: ='ビジネス基礎（Day5)'!C2 -> #DIV/0! | K9: ='ビジネス基礎（Day5)'!D2 -> #DIV/0! | L9: ='ビジネス基礎（Day5)'!E2 -> #DIV/0! | M9: ='ビジネス基礎（Day5)'!F2 -> #DIV/0! | N9: ='ビジネス基礎（Day5)'!G2 -> #DIV/0! | O9: ='ビジネス基礎（Day5)'!H2 -> #DIV/0! | ... Q9: ='ビジネス基礎（Day5)'!J2 -> #DIV/0!
D10: FY2024 | H10: - | I10: - | J10: - | K10: - | L10: - | M10: - | N10: - | O10: - | P10: - | Q10: -
D11: FY2023 | H11: 4.6143498 | I11: 4.4887892 | J11: 4.5784753 | K11: 4.5426009 | L11: 4.4887892 | M11: 4.4843049 | N11: 4.5067265 | O11: 4.4977578 | P11: 4.3991031 | Q11: 4.3766816
C12: 差分 | E12: - | G12: - | H12: =H9-H10 -> #DIV/0! | I12: =I9-I10 -> #DIV/0! | J12: =J9-J10 -> #DIV/0! | K12: =K9-K10 -> #DIV/0! | L12: =L9-L10 -> #DIV/0! | M12: =M9-M10 -> #DIV/0! | N12: =N9-N10 -> #DIV/0! | O12: =O9-O10 -> #DIV/0! | ... Q12: =Q9-Q10 -> #DIV/0!
C13: ビジネス応用 （Day6） | D13: FY2025 | H13: =#REF! -> #REF! | I13: =#REF! -> #REF! | J13: =#REF! -> #REF! | K13: =#REF! -> #REF! | L13: =#REF! -> #REF! | M13: =#REF! -> #REF! | N13: =#REF! -> #REF! | O13: =#REF! -> #REF! | ... Q13: =#REF! -> #REF!
D14: FY2024 | H14: 4.3545455 | I14: 4.3545455 | J14: 4.6 | K14: 4.3363636 | L14: 4.2545455 | M14: 4.3 | N14: 4.2545455 | O14: 4.1681818 | P14: 4.3772727 | Q14: 4.5
D15: FY2023 | H15: 4.5084746 | I15: 4.5028249 | J15: 4.5932203 | K15: 4.4350282 | L15: 4.4011299 | M15: 4.4067797 | N15: 4.4067797 | O15: 4.3841808 | P15: 4.4971751 | Q15: 4.220339
C16: 差分 | E16: - | G16: - | H16: =H13-H14 -> #REF! | I16: =I13-I14 -> #REF! | J16: =J13-J14 -> #REF! | K16: =K13-K14 -> #REF! | L16: =L13-L14 -> #REF! | M16: =M13-M14 -> #REF! | N16: =N13-N14 -> #REF! | O16: =O13-O14 -> #REF! | ... Q16: =Q13-Q14 -> #REF!
B18: 研修コース名 | D18: 年度 | E18: テスト結果 | H18: アンケート結果
E19: 全体
E20: 平均点 | F20: 中央値 | G20: 修了率 | H20: 総合 評価 | I20: 目的 達成度 | J20: 学習 理解度 | K20: 業務 適用度 | L20: 講義 評価 | M20: 演習 評価 | N20: 教材 評価 | O20: 講師 評価 | P20: 研修 日数 | Q20: 学習 環境
B21: IT技術基礎 | C21: ITサービスの キホン | D21: FY2025 | E21: =#REF! -> #REF! | F21: =#REF! -> #REF! | G21: =#REF! -> #REF! | H21: =#REF! -> #REF! | I21: =#REF! -> #REF! | J21: =#REF! -> #REF! | K21: =#REF! -> #REF! | L21: =#REF! -> #REF! | ... Q21: =#REF! -> #REF!
D22: FY2024 | E22: 93.333333 | G22: 0.95698925 | H22: 4.4731183 | I22: 4.4802867 | J22: 4.5232975 | K22: 4.4910394 | L22: 4.3261649 | M22: 4.218638 | N22: 4.4086022 | O22: 4.5125448 | P22: 4.3189964 | Q22: 4.3620072
D23: FY2023 | E23: 93.706897 | G23: 0.95689655 | H23: 4.4502165 | I23: 4.3506494 | J23: 4.3852814 | K23: 4.1515152 | L23: 4.2164502 | M23: 4.1948052 | N23: 4.2987013 | O23: 4.3549784 | P23: 4.2640693 | Q23: 4.2554113
C24: 差分 | E24: =E21-E22 -> #REF! | G24: =G21-G22 -> #REF! | H24: =H21-H22 -> #REF! | I24: =I21-I22 -> #REF! | J24: =J21-J22 -> #REF! | K24: =K21-K22 -> #REF! | L24: =L21-L22 -> #REF! | M24: =M21-M22 -> #REF! | N24: =N21-N22 -> #REF! | ... Q24: =Q21-Q22 -> #REF!
C25: データベース 技術入門 | D25: FY2025 | E25: =#REF! -> #REF! | F25: =#REF! -> #REF! | G25: =#REF! -> #REF! | H25: =#REF! -> #REF! | I25: =#REF! -> #REF! | J25: =#REF! -> #REF! | K25: =#REF! -> #REF! | L25: =#REF! -> #REF! | ... Q25: =#REF! -> #REF!
D26: FY2024 | E26: 90.340502 | G26: 0.94265233 | H26: 4.6582734 | I26: 4.5323741 | J26: 4.3633094 | K26: 4.4100719 | L26: 4.4460432 | M26: 4.4604317 | N26: 4.4640288 | O26: 4.5359712 | P26: 4.1582734 | Q26: 4.5611511
D27: FY2023 | E27: 88.87931 | G27: 0.88793103 | H27: 4.637931 | I27: 4.4525862 | J27: 4.1939655 | K27: 4.237069 | L27: 4.3922414 | M27: 4.3922414 | N27: 4.4051724 | O27: 4.512931 | P27: 4.0603448 | Q27: 4.4741379
C28: 差分 | E28: =E25-E26 -> #REF! | G28: =G25-G26 -> #REF! | H28: =H25-H26 -> #REF! | I28: =I25-I26 -> #REF! | J28: =J25-J26 -> #REF! | K28: =K25-K26 -> #REF! | L28: =L25-L26 -> #REF! | M28: =M25-M26 -> #REF! | N28: =N25-N26 -> #REF! | ... Q28: =Q25-Q26 -> #REF!
C29: Web技術 入門 | D29: FY2025 | E29: =#REF! -> #REF! | F29: =#REF! -> #REF! | G29: =#REF! -> #REF! | H29: =#REF! -> #REF! | I29: =#REF! -> #REF! | J29: =#REF! -> #REF! | K29: =#REF! -> #REF! | L29: =#REF! -> #REF! | ... Q29: =#REF! -> #REF!
D30: FY2024 | E30: 94.086022 | G30: 0.96415771 | H30: 4.6449275 | I30: 4.5869565 | J30: 4.5072464 | K30: 4.4057971 | L30: 4.5362319 | M30: 4.5289855 | N30: 4.5144928 | O30: 4.576087 | P30: 4.1449275 | Q30: 4.4818841
D31: FY2023 | E31: 94.137931 | G31: 0.96551724 | H31: 4.5818966 | I31: 4.5215517 | J31: 4.3577586 | K31: 4.262931 | L31: 4.4525862 | M31: 4.4655172 | N31: 4.4051724 | O31: 4.5991379 | P31: 3.9525862 | Q31: 4.4612069
C32: 差分 | E32: =E29-E30 -> #REF! | G32: =G29-G30 -> #REF! | H32: =H29-H30 -> #REF! | I32: =I29-I30 -> #REF! | J32: =J29-J30 -> #REF! | K32: =K29-K30 -> #REF! | L32: =L29-L30 -> #REF! | M32: =M29-M30 -> #REF! | N32: =N29-N30 -> #REF! | ... Q32: =Q29-Q30 -> #REF!
B34: 研修コース名 | D34: 年度 | E34: テスト結果 | H34: アンケート結果
E35: 全体
E36: 平均点 | F36: 中央値 | G36: 修了率 | H36: 総合 評価 | I36: 目的 達成度 | J36: 学習 理解度 | K36: 業務 適用度 | L36: 講義 評価 | M36: 演習 評価 | N36: 教材 評価 | O36: 講師 評価 | P36: 研修 日数 | Q36: 学習 環境
B37: プログラミング | C37: アルゴリズム 入門 | D37: FY2025 | E37: =#REF! -> #REF! | F37: =#REF! -> #REF! | G37: =#REF! -> #REF! | H37: =#REF! -> #REF! | I37: =#REF! -> #REF! | J37: =#REF! -> #REF! | K37: =#REF! -> #REF! | L37: =#REF! -> #REF! | ... Q37: =#REF! -> #REF!
D38: FY2024 | E38: 90.663082 | G38: 0.95698925 | H38: 4.6223022 | I38: 4.5215827 | J38: 4.3561151 | K38: 4.381295 | L38: 4.4460432 | M38: 4.4316547 | N38: 4.4964029 | O38: 4.5935252 | P38: 4.3057554 | Q38: 4.557554
D39: FY2023 | E39: 90.193966 | G39: 0.93103448 | H39: 4.5258621 | I39: 4.3405172 | J39: 4.1163793 | K39: 4.2241379 | L39: 4.3534483 | M39: 4.3491379 | N39: 4.387931 | O39: 4.5043103 | P39: 3.987069 | Q39: 4.4310345
C40: 差分 | E40: =E37-E38 -> #REF! | G40: =G37-G38 -> #REF! | H40: =H37-H38 -> #REF! | I40: =I37-I38 -> #REF! | J40: =J37-J38 -> #REF! | K40: =K37-K38 -> #REF! | L40: =L37-L38 -> #REF! | M40: =M37-M38 -> #REF! | N40: =N37-N38 -> #REF! | ... Q40: =Q37-Q38 -> #REF!
C41: Javaプログラミング基礎 | D41: FY2025 | E41: =#REF! -> #REF! | F41: =#REF! -> #REF! | G41: =#REF! -> #REF! | H41: =#REF! -> #REF! | I41: =#REF! -> #REF! | J41: =#REF! -> #REF! | K41: =#REF! -> #REF! | L41: =#REF! -> #REF! | ... Q41: =#REF! -> #REF!
D42: FY2024 | E42: 87.354839 | G42: 0.7921147 | H42: 4.6415771 | I42: 4.3691756 | J42: 4.0716846 | K42: 4.2222222 | L42: 4.3476703 | M42: 4.3333333 | N42: 4.3727599 | O42: 4.4444444 | P42: 3.9928315 | Q42: 4.4551971
D43: FY2023 | E43: 87.482759 | G43: 0.79741379 | H43: 4.5301724 | I43: 4.2456897 | J43: 3.8275862 | K43: 4.012931 | L43: 4.2198276 | M43: 4.2456897 | N43: 4.2801724 | O43: 4.4310345 | P43: 3.6939655 | Q43: 4.4525862
...

Sheet ビジネス基礎（Day5)
A1: 総合評価 | B1: 目的達成度 | C1: 学習理解度 | D1: 業務適用度 | E1: 講義評価 | F1: 演習評価 | G1: 教材評価 | H1: 講師評価 | I1: 研修日程 | J1: 学習環境
A2: =AG5 -> #DIV/0! | B2: =G5 -> #DIV/0! | C2: =H5 -> #DIV/0! | D2: =M5 -> #DIV/0! | E2: =P5 -> #DIV/0! | F2: =S5 -> #DIV/0! | G2: =V5 -> #DIV/0! | H2: =Y5 -> #DIV/0! | I2: =AB5 -> #DIV/0! | J2: =AE5 -> #DIV/0!
M3: ※問８を参照！
G4: 目的達成 | H4: 学習 | I4: FA | M4: 業務適用度 | N4: 業務 | P4: 講義 | Q4: 【複数回答】 | R4: FA | S4: 演習 | T4: 【複数回答】 | U4: FA | V4: 教材 | W4: 【複数回答】 | X4: FA | Y4: 講師 | Z4: 【複数回答】 | AA4: FA | AB4: 研修日数 | AC4: 【複数回答】 | AD4: FA | AE4: 受講環境 | AF4: FA | AG4: 総合満足 | AH4: FA
F5: =AVERAGE(F8:F300) -> #DIV/0! | G5: =AVERAGE(G9:G300) -> #DIV/0! | H5: =AVERAGE(H9:H300) -> #DIV/0! | J5: =AVERAGE(J8:J300) -> #DIV/0! | M5: =AVERAGE(M9:M300) -> #DIV/0! | N5: =AVERAGE(N9:N300) -> #DIV/0! | O5: =AVERAGE(M8:M300) -> #DIV/0! | P5: =AVERAGE(P9:P300) -> #DIV/0! | S5: =AVERAGE(S9:S300) -> #DIV/0! | V5: =AVERAGE(V9:V300) -> #DIV/0! | Y5: =AVERAGE(Y9:Y300) -> #DIV/0! | AB5: =AVERAGE(AB9:AB300) -> #DIV/0! | AE5: =AVERAGE(AE9:AE300) -> #DIV/0! | AG5: =AVERAGE(AG9:AG300) -> #DIV/0!
F7: 1.単一選択 | G7: 2.単一選択 | H7: 3.単一選択 | I7: 4.記述回答 | J7: 5.単一選択 | K7: 6.単一選択 | L7: 5.単一選択 | M7: 6.単一選択 | N7: 7.単一選択 | O7: 8.単一選択 | P7: 9.単一選択 | Q7: 10.複数選択 | R7: 11.記述回答 | S7: 12.単一選択 | T7: 13.複数選択 | U7: 14.記述回答 | V7: 15.単一選択 | W7: 16.複数選択 | X7: 17.記述回答 | Y7: 18.単一選択 | Z7: 19.複数選択 | AA7: 20.記述回答 | AB7: 21.単一選択 | AC7: 22.単一選択 | AD7: 23.記述回答 | AE7: 24.単一選択 | AF7: 25.記述回答 | AG7: 26.単一選択 | AH7: 27.記述回答
A8: 年度 | B8: コースコード | C8: レッスン回数 | D8: ID | E8: 受講者名 | F8: 問1,本研修の学習内容はあなたが期待した通りの内容でしたか？ | G8: 問2,研修の目的は、達成されましたか？ | H8: 問3,学習した内容は理解できましたか？ | I8: 問4,問1～3について、評価の理由と今後に向けたご意見・ご要望をご記入ください。 | J8: 問5,本科目の達成イメージを明確にし、自分がやるべきことを考え、実行することができましたか。 | K8: 問6,本科目の中で、行動の結果をニュートラルに捉え、原因分析をしたり、周囲からのフィードバックを受け止めて次に活かすためにどうしたらよいかを考えましたか？ | L8: 問7,研修中に、新たな気づきを得る、または、学習内容の重要性を認識する機会がありましたか？ | M8: 問8,学習内容をあなたの業務に適用する見通しやイメージをもつことはできましたか？ | N8: 問9,学習内容を業務で活用し、成果を出せる（内容を理解できる、困難があっても対処できる）という期待・自信はもてましたか？ | O8: 問10,学習内容を業務に活用して成果をあげるために、どのような点に注意しながらやればよいかのイメージができましたか？ | P8: 問11,講義の進め方や内容は、あなたが研修の目的を達成する上で有効でしたか？ | Q8: 問12,問11にて2以下とした方のみ評価の理由として当てはまるものを全て選択してください | R8: 問13,問11に関するコメントがある方はコメントを記載してください | S8: 問14,演習（実習）の進め方や内容は、あなたが研修の目的を達成する上で有効でしたか？ | T8: 問15,問14にて2以下とした方のみ評価の理由として当てはまるものを全て選択してください | U8: 問16,問14に関するコメントがある方はコメントを記載してください | V8: 問17,教材の内容は、あなたが研修の目的を達成する上で有効でしたか？ | W8: 問18,問17にて2以下とした方のみ評価の理由として当てはまるものを選択してください | X8: 問19,問17に関するコメントがある方はコメントを記載してください | Y8: 問20,講師の指導は、あなたが研修の目的を達成する上で有効でしたか？ | Z8: 問21,問20にて2以下とした方のみ評価の理由として当てはまるもの | AA8: 問22,問20に関するコメントがある方はコメントを記載してください | AB8: 問23,学習内容に対して、研修の日数は適切でしたか？ | AC8: 問24,問23にて2以下とした方のみ評価の理由として当てはまるもの | AD8: 問25,問23に関するコメントがある方はコメントを記載してください | AE8: 問26,受講環境（オンラインの場合は、通信環境・ツールの使い勝手等を含む）は良好でしたか？ | AF8: 問27,問26に関するコメントがある方はコメントを記載してください | AG8: 問28,本研修は全体を通してあなたにとって有意義なものでしたか？ | AH8: 問29,問28に関するコメントがある方はコメントを記載してください
